<robot name="quad">

<link name="quad1">
</link>

<link name="quadr">
  <visual>
    <origin xyz="0 0 0" rpy="0 0 0.785" />
    <geometry>
      <box size="0.4 0.4 0.11" />
    </geometry>
    <material name="green">
      <color rgba="0 .2 0 1" />
    </material>
  </visual>
</link>

<link name="link1">
  <visual>
    <origin xyz="0 0 0" rpy="0 0 0" />
    <geometry>
      <box size="2.2 .1 .1" />
    </geometry>
    <material name="blue">
      <color rgba="0 0 .4 1" />
    </material>
  </visual>
</link>

<link name="link2">
  <visual>
    <origin xyz="0 0 0" rpy="0 0 0" />
    <geometry>
      <box size="0.1 2.2 .1" />
    </geometry>
    <material name="blue" />
  </visual>
</link>

<link name="mot1">
  <visual>
    <origin xyz="0 0 0" rpy="0 0 0" />
    <geometry>
      <cylinder radius="0.1" length="0.2" />
    </geometry>
    <material name="purple">
      <color rgba=".3 0 .3 1" />
    </material>
  </visual>
</link>

<link name="mot2">
  <visual>
    <origin xyz="0 0 0" rpy="0 0 0" />
    <geometry>
      <cylinder radius="0.1" length="0.2" />
    </geometry>
    <material name="purple"/>
  </visual>
</link>

<link name="mot3">
  <visual>
    <origin xyz="0 0 0" rpy="0 0 0" />
    <geometry>
      <cylinder radius="0.1" length="0.2" />
    </geometry>
    <material name="purple"/>
  </visual>
</link>

<link name="mot4">
  <visual>
    <origin xyz="0 0 0" rpy="0 0 0" />
    <geometry>
      <cylinder radius="0.1" length="0.2" />
    </geometry>
    <material name="purple"/>
  </visual>
</link>

<link name="q1ballrxl">
</link>

<link name="q1ballryl">
  <visual>
    <origin xyz="0 0 -1" rpy="0 0 0" />
    <geometry>
      <cylinder radius="0.005" length="2" />
    </geometry>
    <material name="purple"/>
  </visual>
</link>

<link name="ball">
  <visual>
    <origin xyz="0 0 0" rpy="0 0 0" />
    <geometry>
      <sphere radius="0.07"/>
    </geometry>
    <material name="green"/>
  </visual>
</link>

<joint name="balljoint" type="fixed">
    <origin xyz="0 0 -2" rpy="0 0 0" />
    <parent link="q1ballryl" />    
    <child link="ball" /> 
</joint>

<joint name="joint1" type="fixed">
    <origin xyz="0 0 0" rpy="0 0 0" />
    <parent link="quadr" />    
    <child link="link1" /> 
</joint>

<joint name="joint2" type="fixed">
    <origin xyz="0 0 0" rpy="0 0 0" />
    <parent link="quadr" />    
    <child link="link2" /> 
</joint>

<joint name="joint3" type="fixed">
    <origin xyz="1.1 0 0.05" rpy="0 0 0" />
    <parent link="quadr" />    
    <child link="mot1" /> 
</joint>

<joint name="joint4" type="fixed">
    <origin xyz="-1.1 0 0.05" rpy="0 0 0" />
    <parent link="quadr" />    
    <child link="mot2" /> 
</joint>

<joint name="joint5" type="fixed">
    <origin xyz="0 1.1 0.05" rpy="0 0 0" />
    <parent link="quadr" />    
    <child link="mot3" /> 
</joint>

<joint name="joint6" type="fixed">
    <origin xyz="0 -1.1 0.05" rpy="0 0 0" />
    <parent link="quadr" />    
    <child link="mot4" /> 
</joint>

<joint name="quadrxy" type="continuous">
    <axis xyz="1 0 0" />
    <origin xyz = "0 0 0" rpy="0 0 0" />
    <parent link="quad1" />
    <child link="quadr" />
</joint>

<joint name="q1ballrx" type="continuous">
    <axis xyz="1 0 0" />
    <origin xyz = "0 0 0" rpy="0 0 0" />
    <parent link="quad1" />
    <child link="q1ballrxl" />
</joint>

<joint name="q1ballry" type="continuous">
    <axis xyz="0 1 0" />
    <origin xyz = "0 0 0" rpy="0 0 0" />
    <parent link="q1ballrxl" />
    <child link="q1ballryl" />
</joint>

</robot>
